Workbook

Sheet Summary
A1: PC-2 breadboard kit: parts cost
A2: AUD including GST, cheapest suitable source per line, prices checked 2026-10-24. Freight, PCBs and packaging not included.
B4: Tier 1 | C4: Tier 2 | D4: Tier 3
A5: Kits bought | B5: =Assumptions!$B$4 -> 1 | C5: =Assumptions!$B$5 -> 10 | D5: =Assumptions!$B$6 -> 100
A6: Parts cost per kit | B6: =BOM!H55 -> 655.3066 | C6: =BOM!I55 -> 509.5845 | D6: =BOM!J55 -> 478.27793
A7: Parts cost for the whole order | B7: =B6*B5 -> 655.3066 | C7: =C6*C5 -> 5095.845 | D7: =D6*D5 -> 47827.793
A8: Lines with one suitable source | B8: =COUNTIF(BOM!G2:G54,1) -> 11
A9: Lines with no price | B9: =COUNTIF(BOM!G2:G54,0) -> 0
A11: Cost by group (per kit)
A12: Group | B12: Tier 1 | C12: Tier 2 | D12: Tier 3
A13: Logic (74HCT) | B13: =SUMIFS(BOM!H2:H54,BOM!B2:B54,$A13) -> 60.031 | C13: =SUMIFS(BOM!I2:I54,BOM!B2:B54,$A13) -> 42.7365 | D13: =SUMIFS(BOM!J2:J54,BOM!B2:B54,$A13) -> 36.4142
A14: Timer | B14: =SUMIFS(BOM!H2:H54,BOM!B2:B54,$A14) -> 3 | C14: =SUMIFS(BOM!I2:I54,BOM!B2:B54,$A14) -> 2.6224 | D14: =SUMIFS(BOM!J2:J54,BOM!B2:B54,$A14) -> 2.0284
A15: Memory | B15: =SUMIFS(BOM!H2:H54,BOM!B2:B54,$A15) -> 96.987 | C15: =SUMIFS(BOM!I2:I54,BOM!B2:B54,$A15) -> 92.763 | D15: =SUMIFS(BOM!J2:J54,BOM!B2:B54,$A15) -> 89.771
A16: Semiconductors | B16: =SUMIFS(BOM!H2:H54,BOM!B2:B54,$A16) -> 1.6588 | C16: =SUMIFS(BOM!I2:I54,BOM!B2:B54,$A16) -> 1.0472 | D16: =SUMIFS(BOM!J2:J54,BOM!B2:B54,$A16) -> 0.6512
A17: Display | B17: =SUMIFS(BOM!H2:H54,BOM!B2:B54,$A17) -> 14.564 | C17: =SUMIFS(BOM!I2:I54,BOM!B2:B54,$A17) -> 10.252 | D17: =SUMIFS(BOM!J2:J54,BOM!B2:B54,$A17) -> 7.964
A18: Indicators | B18: =SUMIFS(BOM!H2:H54,BOM!B2:B54,$A18) -> 39.4768 | C18: =SUMIFS(BOM!I2:I54,BOM!B2:B54,$A18) -> 28.985 | D18: =SUMIFS(BOM!J2:J54,BOM!B2:B54,$A18) -> 28.985
A19: Resistors | B19: =SUMIFS(BOM!H2:H54,BOM!B2:B54,$A19) -> 11.3982 | C19: =SUMIFS(BOM!I2:I54,BOM!B2:B54,$A19) -> 7.3227 | D19: =SUMIFS(BOM!J2:J54,BOM!B2:B54,$A19) -> 6.4427
A20: Capacitors | B20: =SUMIFS(BOM!H2:H54,BOM!B2:B54,$A20) -> 18.9285 | C20: =SUMIFS(BOM!I2:I54,BOM!B2:B54,$A20) -> 13.659 | D20: =SUMIFS(BOM!J2:J54,BOM!B2:B54,$A20) -> 11.1485
A21: Controls | B21: =SUMIFS(BOM!H2:H54,BOM!B2:B54,$A21) -> 3.9373 | C21: =SUMIFS(BOM!I2:I54,BOM!B2:B54,$A21) -> 3.2465 | D21: =SUMIFS(BOM!J2:J54,BOM!B2:B54,$A21) -> 3.065
A22: Switches | B22: =SUMIFS(BOM!H2:H54,BOM!B2:B54,$A22) -> 19.356 | C22: =SUMIFS(BOM!I2:I54,BOM!B2:B54,$A22) -> 16.987 | D22: =SUMIFS(BOM!J2:J54,BOM!B2:B54,$A22) -> 15.5108
A23: Build | B23: =SUMIFS(BOM!H2:H54,BOM!B2:B54,$A23) -> 357.709 | C23: =SUMIFS(BOM!I2:I54,BOM!B2:B54,$A23) -> 262.7218 | D23: =SUMIFS(BOM!J2:J54,BOM!B2:B54,$A23) -> 249.54193
A24: Power | B24: =SUMIFS(BOM!H2:H54,BOM!B2:B54,$A24) -> 18.115 | C24: =SUMIFS(BOM!I2:I54,BOM!B2:B54,$A24) -> 17.7454 | D24: =SUMIFS(BOM!J2:J54,BOM!B2:B54,$A24) -> 17.5892
A25: Programmer | B25: =SUMIFS(BOM!H2:H54,BOM!B2:B54,$A25) -> 10.145 | C25: =SUMIFS(BOM!I2:I54,BOM!B2:B54,$A25) -> 9.496 | D25: =SUMIFS(BOM!J2:J54,BOM!B2:B54,$A25) -> 9.166

Sheet Assumptions
A1: PC-2 kit costed BOM: assumptions
A3: GST rate | B3: 0.1 | C3: Australian GST. Added to every price recorded as ex-GST.
A4: Kits in tier 1 | B4: 1 | C4: Buying for one kit (the prototype).
A5: Kits in tier 2 | B5: 10 | C5: A small first batch.
A6: Kits in tier 3 | B6: 100 | C6: A production batch.
A7: Prices checked | B7: 2026-10-24 | C7: Every price was read from the supplier's product page on this date.
A10: How costs are worked out
A11: 1. Each line's quantity per kit is multiplied by the kits in the tier, then rounded up to whole packs.
A12: 2. A supplier's quantity-break price is used only when the packs bought reach that break; otherwise the next lower price applies.
A13: 3. All prices are converted to AUD including GST.
A14: 4. For each line, the cheapest suitable source at each tier is chosen. Freight is not included.
A16: GST assumptions to confirm
A17: - Mouser Australia pages state no GST treatment; their prices are assumed ex-GST.
A18: - Jaycar pages state no GST treatment; their prices are assumed GST-inclusive (retail).
A19: - element14 and DigiKey list ex-GST prices; Core Electronics prices are recorded as each record's incl_gst flag says.
A21: Not included
A22: - PCBs, IC sockets, packaging, printed book, freight, merchant fees and labour.
A24: Editing
... A26: - On the Prices sheet, set Suitable to N to drop a source from costing.

Sheet BOM
A1: ID | B1: Group | C1: Part | D1: Description | E1: Qty per kit | F1: Used in | G1: Suitable sources | H1: Cost per kit @T1 | I1: Cost per kit @T2 | J1: Cost per kit @T3 | K1: Cheapest @T1 | L1: Cheapest @T3 | M1: Flag
A2: H00 | B2: Logic (74HCT) | C2: 74HCT00 | D2: Quad NAND, DIP-14 | E2: 1 | F2: see netlist | G2: =COUNTIFS(Prices!$A$2:$A$106,$A2,Prices!$L$2:$L$106,"Y",Prices!$E$2:$E$106,">0") -> 2 | H2: =_xlfn.MINIFS(Prices!$W$2:$W$106,Prices!$A$2:$A$106,$A2,Prices!$L$2:$L$106,"Y",Prices!$W$2:$W$106,">0") -> 1.265 | I2: =_xlfn.MINIFS(Prices!$X$2:$X$106,Prices!$A$2:$A$106,$A2,Prices!$L$2:$L$106,"Y",Prices!$X$2:$X$106,">0") -> 0.9031 | J2: =_xlfn.MINIFS(Prices!$Y$2:$Y$106,Prices!$A$2:$A$106,$A2,Prices!$L$2:$L$106,"Y",Prices!$Y$2:$Y$106,">0") -> 0.7117 | K2: =IFERROR(INDEX(Prices!$B$2:$B$106,MATCH($A2&"|"&TEXT($H2,"0.0000")&"|Y",Prices!$Z$2:$Z$106,0)),"none") -> Mouser Australia | L2: =IFERROR(INDEX(Prices!$B$2:$B$106,MATCH($A2&"|"&TEXT($J2,"0.0000")&"|Y",Prices!$AA$2:$AA$106,0)),"none") -> Mouser Australia | M2: =IF($G2=0,"NO PRICE",IF($G2=1,"Single source",""))
A3: H02 | B3: Logic (74HCT) | C3: 74HCT02 | D3: Quad NOR, DIP-14 | E3: 1 | F3: see netlist | G3: =COUNTIFS(Prices!$A$2:$A$106,$A3,Prices!$L$2:$L$106,"Y",Prices!$E$2:$E$106,">0") -> 2 | H3: =_xlfn.MINIFS(Prices!$W$2:$W$106,Prices!$A$2:$A$106,$A3,Prices!$L$2:$L$106,"Y",Prices!$W$2:$W$106,">0") -> 0.55 | I3: =_xlfn.MINIFS(Prices!$X$2:$X$106,Prices!$A$2:$A$106,$A3,Prices!$L$2:$L$106,"Y",Prices!$X$2:$X$106,">0") -> 0.5 | J3: =_xlfn.MINIFS(Prices!$Y$2:$Y$106,Prices!$A$2:$A$106,$A3,Prices!$L$2:$L$106,"Y",Prices!$Y$2:$Y$106,">0") -> 0.45 | K3: =IFERROR(INDEX(Prices!$B$2:$B$106,MATCH($A3&"|"&TEXT($H3,"0.0000")&"|Y",Prices!$Z$2:$Z$106,0)),"none") -> Wiltronics (AU) | L3: =IFERROR(INDEX(Prices!$B$2:$B$106,MATCH($A3&"|"&TEXT($J3,"0.0000")&"|Y",Prices!$AA$2:$AA$106,0)),"none") -> Wiltronics (AU) | M3: =IF($G3=0,"NO PRICE",IF($G3=1,"Single source",""))
A4: H04 | B4: Logic (74HCT) | C4: 74HCT04 | D4: Hex inverter, DIP-14 | E4: 2 | F4: see netlist | G4: =COUNTIFS(Prices!$A$2:$A$106,$A4,Prices!$L$2:$L$106,"Y",Prices!$E$2:$E$106,">0") -> 2 | H4: =_xlfn.MINIFS(Prices!$W$2:$W$106,Prices!$A$2:$A$106,$A4,Prices!$L$2:$L$106,"Y",Prices!$W$2:$W$106,">0") -> 1.32 | I4: =_xlfn.MINIFS(Prices!$X$2:$X$106,Prices!$A$2:$A$106,$A4,Prices!$L$2:$L$106,"Y",Prices!$X$2:$X$106,">0") -> 1.2 | J4: =_xlfn.MINIFS(Prices!$Y$2:$Y$106,Prices!$A$2:$A$106,$A4,Prices!$L$2:$L$106,"Y",Prices!$Y$2:$Y$106,">0") -> 0.96 | K4: =IFERROR(INDEX(Prices!$B$2:$B$106,MATCH($A4&"|"&TEXT($H4,"0.0000")&"|Y",Prices!$Z$2:$Z$106,0)),"none") -> Wiltronics (AU) | L4: =IFERROR(INDEX(Prices!$B$2:$B$106,MATCH($A4&"|"&TEXT($J4,"0.0000")&"|Y",Prices!$AA$2:$AA$106,0)),"none") -> Wiltronics (AU) | M4: =IF($G4=0,"NO PRICE",IF($G4=1,"Single source",""))
A5: H08 | B5: Logic (74HCT) | C5: 74HCT08 | D5: Quad AND, DIP-14 | E5: 2 | F5: see netlist | G5: =COUNTIFS(Prices!$A$2:$A$106,$A5,Prices!$L$2:$L$106,"Y",Prices!$E$2:$E$106,">0") -> 3 | H5: =_xlfn.MINIFS(Prices!$W$2:$W$106,Prices!$A$2:$A$106,$A5,Prices!$L$2:$L$106,"Y",Prices!$W$2:$W$106,">0") -> 3.014 | I5: =_xlfn.MINIFS(Prices!$X$2:$X$106,Prices!$A$2:$A$106,$A5,Prices!$L$2:$L$106,"Y",Prices!$X$2:$X$106,">0") -> 1.958 | J5: =_xlfn.MINIFS(Prices!$Y$2:$Y$106,Prices!$A$2:$A$106,$A5,Prices!$L$2:$L$106,"Y",Prices!$Y$2:$Y$106,">0") -> 1.6258 | K5: =IFERROR(INDEX(Prices!$B$2:$B$106,MATCH($A5&"|"&TEXT($H5,"0.0000")&"|Y",Prices!$Z$2:$Z$106,0)),"none") -> element14 Australia | L5: =IFERROR(INDEX(Prices!$B$2:$B$106,MATCH($A5&"|"&TEXT($J5,"0.0000")&"|Y",Prices!$AA$2:$AA$106,0)),"none") -> element14 Australia | M5: =IF($G5=0,"NO PRICE",IF($G5=1,"Single source",""))
A6: H32 | B6: Logic (74HCT) | C6: 74HCT32 | D6: Quad OR, DIP-14 | E6: 1 | F6: see netlist | G6: =COUNTIFS(Prices!$A$2:$A$106,$A6,Prices!$L$2:$L$106,"Y",Prices!$E$2:$E$106,">0") -> 3 | H6: =_xlfn.MINIFS(Prices!$W$2:$W$106,Prices!$A$2:$A$106,$A6,Prices!$L$2:$L$106,"Y",Prices!$W$2:$W$106,">0") -> 0.66 | I6: =_xlfn.MINIFS(Prices!$X$2:$X$106,Prices!$A$2:$A$106,$A6,Prices!$L$2:$L$106,"Y",Prices!$X$2:$X$106,">0") -> 0.6 | J6: =_xlfn.MINIFS(Prices!$Y$2:$Y$106,Prices!$A$2:$A$106,$A6,Prices!$L$2:$L$106,"Y",Prices!$Y$2:$Y$106,">0") -> 0.48 | K6: =IFERROR(INDEX(Prices!$B$2:$B$106,MATCH($A6&"|"&TEXT($H6,"0.0000")&"|Y",Prices!$Z$2:$Z$106,0)),"none") -> Wiltronics (AU) | L6: =IFERROR(INDEX(Prices!$B$2:$B$106,MATCH($A6&"|"&TEXT($J6,"0.0000")&"|Y",Prices!$AA$2:$AA$106,0)),"none") -> Wiltronics (AU) | M6: =IF($G6=0,"NO PRICE",IF($G6=1,"Single source",""))
A7: H86 | B7: Logic (74HCT) | C7: 74HCT86 | D7: Quad XOR, DIP-14 | E7: 2 | F7: see netlist | G7: =COUNTIFS(Prices!$A$2:$A$106,$A7,Prices!$L$2:$L$106,"Y",Prices!$E$2:$E$106,">0") -> 1 | H7: =_xlfn.MINIFS(Prices!$W$2:$W$106,Prices!$A$2:$A$106,$A7,Prices!$L$2:$L$106,"Y",Prices!$W$2:$W$106,">0") -> 3.608 | I7: =_xlfn.MINIFS(Prices!$X$2:$X$106,Prices!$A$2:$A$106,$A7,Prices!$L$2:$L$106,"Y",Prices!$X$2:$X$106,">0") -> 2.574 | J7: =_xlfn.MINIFS(Prices!$Y$2:$Y$106,Prices!$A$2:$A$106,$A7,Prices!$L$2:$L$106,"Y",Prices!$Y$2:$Y$106,">0") -> 2.0328 | K7: =IFERROR(INDEX(Prices!$B$2:$B$106,MATCH($A7&"|"&TEXT($H7,"0.0000")&"|Y",Prices!$Z$2:$Z$106,0)),"none") -> Mouser Australia | L7: =IFERROR(INDEX(Prices!$B$2:$B$106,MATCH($A7&"|"&TEXT($J7,"0.0000")&"|Y",Prices!$AA$2:$AA$106,0)),"none") -> Mouser Australia | M7: =IF($G7=0,"NO PRICE",IF($G7=1,"Single source","")) -> Single source
A8: H107 | B8: Logic (74HCT) | C8: 74HCT107 (CD74HCT107E) | D8: Dual JK flip-flop, DIP-14 | E8: 1 | F8: see netlist | G8: =COUNTIFS(Prices!$A$2:$A$106,$A8,Prices!$L$2:$L$106,"Y",Prices!$E$2:$E$106,">0") -> 1 | H8: =_xlfn.MINIFS(Prices!$W$2:$W$106,Prices!$A$2:$A$106,$A8,Prices!$L$2:$L$106,"Y",Prices!$W$2:$W$106,">0") -> 4.642 | I8: =_xlfn.MINIFS(Prices!$X$2:$X$106,Prices!$A$2:$A$106,$A8,Prices!$L$2:$L$106,"Y",Prices!$X$2:$X$106,">0") -> 3.476 | J8: =_xlfn.MINIFS(Prices!$Y$2:$Y$106,Prices!$A$2:$A$106,$A8,Prices!$L$2:$L$106,"Y",Prices!$Y$2:$Y$106,">0") -> 2.838 | K8: =IFERROR(INDEX(Prices!$B$2:$B$106,MATCH($A8&"|"&TEXT($H8,"0.0000")&"|Y",Prices!$Z$2:$Z$106,0)),"none") -> Mouser Australia | L8: =IFERROR(INDEX(Prices!$B$2:$B$106,MATCH($A8&"|"&TEXT($J8,"0.0000")&"|Y",Prices!$AA$2:$AA$106,0)),"none") -> Mouser Australia | M8: =IF($G8=0,"NO PRICE",IF($G8=1,"Single source","")) -> Single source
A9: H138 | B9: Logic (74HCT) | C9: 74HCT138 | D9: 3-to-8 decoder, DIP-16 | E9: 1 | F9: see netlist | G9: =COUNTIFS(Prices!$A$2:$A$106,$A9,Prices!$L$2:$L$106,"Y",Prices!$E$2:$E$106,">0") -> 2 | H9: =_xlfn.MINIFS(Prices!$W$2:$W$106,Prices!$A$2:$A$106,$A9,Prices!$L$2:$L$106,"Y",Prices!$W$2:$W$106,">0") -> 1.1 | I9: =_xlfn.MINIFS(Prices!$X$2:$X$106,Prices!$A$2:$A$106,$A9,Prices!$L$2:$L$106,"Y",Prices!$X$2:$X$106,">0") -> 0.99 | J9: =_xlfn.MINIFS(Prices!$Y$2:$Y$106,Prices!$A$2:$A$106,$A9,Prices!$L$2:$L$106,"Y",Prices!$Y$2:$Y$106,">0") -> 0.79 | K9: =IFERROR(INDEX(Prices!$B$2:$B$106,MATCH($A9&"|"&TEXT($H9,"0.0000")&"|Y",Prices!$Z$2:$Z$106,0)),"none") -> Wiltronics (AU) | L9: =IFERROR(INDEX(Prices!$B$2:$B$106,MATCH($A9&"|"&TEXT($J9,"0.0000")&"|Y",Prices!$AA$2:$AA$106,0)),"none") -> Wiltronics (AU) | M9: =IF($G9=0,"NO PRICE",IF($G9=1,"Single source",""))
A10: H139 | B10: Logic (74HCT) | C10: 74HCT139 | D10: Dual 2-to-4 decoder, DIP-16 | E10: 2 | F10: see netlist | G10: =COUNTIFS(Prices!$A$2:$A$106,$A10,Prices!$L$2:$L$106,"Y",Prices!$E$2:$E$106,">0") -> 1 | H10: =_xlfn.MINIFS(Prices!$W$2:$W$106,Prices!$A$2:$A$106,$A10,Prices!$L$2:$L$106,"Y",Prices!$W$2:$W$106,">0") -> 3.388 | I10: =_xlfn.MINIFS(Prices!$X$2:$X$106,Prices!$A$2:$A$106,$A10,Prices!$L$2:$L$106,"Y",Prices!$X$2:$X$106,">0") -> 2.42 | J10: =_xlfn.MINIFS(Prices!$Y$2:$Y$106,Prices!$A$2:$A$106,$A10,Prices!$L$2:$L$106,"Y",Prices!$Y$2:$Y$106,">0") -> 1.9338 | K10: =IFERROR(INDEX(Prices!$B$2:$B$106,MATCH($A10&"|"&TEXT($H10,"0.0000")&"|Y",Prices!$Z$2:$Z$106,0)),"none") -> Mouser Australia | L10: =IFERROR(INDEX(Prices!$B$2:$B$106,MATCH($A10&"|"&TEXT($J10,"0.0000")&"|Y",Prices!$AA$2:$AA$106,0)),"none") -> Mouser Australia | M10: =IF($G10=0,"NO PRICE",IF($G10=1,"Single source","")) -> Single source
A11: H157 | B11: Logic (74HCT) | C11: 74HCT157 | D11: Quad 2-to-1 mux, DIP-16 | E11: 2 | F11: see netlist | G11: =COUNTIFS(Prices!$A$2:$A$106,$A11,Prices!$L$2:$L$106,"Y",Prices!$E$2:$E$106,">0") -> 2 | H11: =_xlfn.MINIFS(Prices!$W$2:$W$106,Prices!$A$2:$A$106,$A11,Prices!$L$2:$L$106,"Y",Prices!$W$2:$W$106,">0") -> 3.454 | I11: =_xlfn.MINIFS(Prices!$X$2:$X$106,Prices!$A$2:$A$106,$A11,Prices!$L$2:$L$106,"Y",Prices!$X$2:$X$106,">0") -> 2.442 | J11: =_xlfn.MINIFS(Prices!$Y$2:$Y$106,Prices!$A$2:$A$106,$A11,Prices!$L$2:$L$106,"Y",Prices!$Y$2:$Y$106,">0") -> 1.9778 | K11: =IFERROR(INDEX(Prices!$B$2:$B$106,MATCH($A11&"|"&TEXT($H11,"0.0000")&"|Y",Prices!$Z$2:$Z$106,0)),"none") -> Mouser Australia | L11: =IFERROR(INDEX(Prices!$B$2:$B$106,MATCH($A11&"|"&TEXT($J11,"0.0000")&"|Y",Prices!$AA$2:$AA$106,0)),"none") -> Mouser Australia | M11: =IF($G11=0,"NO PRICE",IF($G11=1,"Single source",""))
A12: H161 | B12: Logic (74HCT) | C12: 74HCT161 | D12: 4-bit counter, DIP-16 | E12: 2 | F12: see netlist | G12: =COUNTIFS(Prices!$A$2:$A$106,$A12,Prices!$L$2:$L$106,"Y",Prices!$E$2:$E$106,">0") -> 1 | H12: =_xlfn.MINIFS(Prices!$W$2:$W$106,Prices!$A$2:$A$106,$A12,Prices!$L$2:$L$106,"Y",Prices!$W$2:$W$106,">0") -> 4.268 | I12: =_xlfn.MINIFS(Prices!$X$2:$X$106,Prices!$A$2:$A$106,$A12,Prices!$L$2:$L$106,"Y",Prices!$X$2:$X$106,">0") -> 3.102 | J12: =_xlfn.MINIFS(Prices!$Y$2:$Y$106,Prices!$A$2:$A$106,$A12,Prices!$L$2:$L$106,"Y",Prices!$Y$2:$Y$106,">0") -> 2.486 | K12: =IFERROR(INDEX(Prices!$B$2:$B$106,MATCH($A12&"|"&TEXT($H12,"0.0000")&"|Y",Prices!$Z$2:$Z$106,0)),"none") -> Mouser Australia | L12: =IFERROR(INDEX(Prices!$B$2:$B$106,MATCH($A12&"|"&TEXT($J12,"0.0000")&"|Y",Prices!$AA$2:$AA$106,0)),"none") -> Mouser Australia | M12: =IF($G12=0,"NO PRICE",IF($G12=1,"Single source","")) -> Single source
A13: H173 | B13: Logic (74HCT) | C13: 74HCT173 (CD74HCT173E) | D13: 4-bit register tri-state, DIP-16 | E13: 9 | F13: see netlist | G13: =COUNTIFS(Prices!$A$2:$A$106,$A13,Prices!$L$2:$L$106,"Y",Prices!$E$2:$E$106,">0") -> 2 | H13: =_xlfn.MINIFS(Prices!$W$2:$W$106,Prices!$A$2:$A$106,$A13,Prices!$L$2:$L$106,"Y",Prices!$W$2:$W$106,">0") -> 10.08 | I13: =_xlfn.MINIFS(Prices!$X$2:$X$106,Prices!$A$2:$A$106,$A13,Prices!$L$2:$L$106,"Y",Prices!$X$2:$X$106,">0") -> 7.2 | J13: =_xlfn.MINIFS(Prices!$Y$2:$Y$106,Prices!$A$2:$A$106,$A13,Prices!$L$2:$L$106,"Y",Prices!$Y$2:$Y$106,">0") -> 7.2 | K13: =IFERROR(INDEX(Prices!$B$2:$B$106,MATCH($A13&"|"&TEXT($H13,"0.0000")&"|Y",Prices!$Z$2:$Z$106,0)),"none") -> Wiltronics (AU) | L13: =IFERROR(INDEX(Prices!$B$2:$B$106,MATCH($A13&"|"&TEXT($J13,"0.0000")&"|Y",Prices!$AA$2:$AA$106,0)),"none") -> Wiltronics (AU) | M13: =IF($G13=0,"NO PRICE",IF($G13=1,"Single source",""))
... A29: R02 | B29: Resistors | C29: Resistor 10 kΩ 1/4 W | D29: 7 used + spares (incl. PROG pull-down and programmer WE pull-up) | E29: 10 | F29: Front panel, Display driver, programmer | G29: =COUNTIFS(Prices!$A$2:$A$106,$A29,Prices!$L$2:$L$106,"Y",Prices!$E$2:$E$106,">0") -> 2 | H29: =_xlfn.MINIFS(Prices!$W$2:$W$106,Prices!$A$2:$A$106,$A29,Prices!$L$2:$L$106,"Y",Prices!$W$2:$W$106,">0") -> 0.649 | I29: =_xlfn.MINIFS(Prices!$X$2:$X$106,Prices!$A$2:$A$106,$A29,Prices!$L$2:$L$106,"Y",Prices!$X$2:$X$106,">0") -> 0.374 | J29: =_xlfn.MINIFS(Prices!$Y$2:$Y$106,Prices!$A$2:$A$106,$A29,Prices!$L$2:$L$106,"Y",Prices!$Y$2:$Y$106,">0") -> 0.374 | K29: =IFERROR(INDEX(Prices!$B$2:$B$106,MATCH($A29&"|"&TEXT($H29,"0.0000")&"|Y",Prices!$Z$2:$Z$106,0)),"none") -> element14 Australia | L29: =IFERROR(INDEX(Prices!$B$2:$B$106,MATCH($A29&"|"&TEXT($J29,"0.0000")&"|Y",Prices!$AA$2:$AA$106,0)),"none") -> element14 Australia | M29: =IF($G29=0,"NO PRICE",IF($G29=1,"Single source",""))
A30: R100k | B30: Resistors | C30: Resistor 100 kΩ 1/4 W | E30: 1 | F30: Clock | G30: =COUNTIFS(Prices!$A$2:$A$106,$A30,Prices!$L$2:$L$106,"Y",Prices!$E$2:$E$106,">0") -> 2 | H30: =_xlfn.MINIFS(Prices!$W$2:$W$106,Prices!$A$2:$A$106,$A30,Prices!$L$2:$L$106,"Y",Prices!$W$2:$W$106,">0") -> 0.0671 | I30: =_xlfn.MINIFS(Prices!$X$2:$X$106,Prices!$A$2:$A$106,$A30,Prices!$L$2:$L$106,"Y",Prices!$X$2:$X$106,">0") -> 0.0671 | J30: =_xlfn.MINIFS(Prices!$Y$2:$Y$106,Prices!$A$2:$A$106,$A30,Prices!$L$2:$L$106,"Y",Prices!$Y$2:$Y$106,">0") -> 0.0429 | K30: =IFERROR(INDEX(Prices!$B$2:$B$106,MATCH($A30&"|"&TEXT($H30,"0.0000")&"|Y",Prices!$Z$2:$Z$106,0)),"none") -> element14 Australia | L30: =IFERROR(INDEX(Prices!$B$2:$B$106,MATCH($A30&"|"&TEXT($J30,"0.0000")&"|Y",Prices!$AA$2:$AA$106,0)),"none") -> Mouser Australia | M30: =IF($G30=0,"NO PRICE",IF($G30=1,"Single source",""))
A31: R470 | B31: Resistors | C31: Resistor 470 Ω 1/4 W | D31: 8 used + spares | E31: 10 | F31: Display | G31: =COUNTIFS(Prices!$A$2:$A$106,$A31,Prices!$L$2:$L$106,"Y",Prices!$E$2:$E$106,">0") -> 2 | H31: =_xlfn.MINIFS(Prices!$W$2:$W$106,Prices!$A$2:$A$106,$A31,Prices!$L$2:$L$106,"Y",Prices!$W$2:$W$106,">0") -> 0.704 | I31: =_xlfn.MINIFS(Prices!$X$2:$X$106,Prices!$A$2:$A$106,$A31,Prices!$L$2:$L$106,"Y",Prices!$X$2:$X$106,">0") -> 0.462 | J31: =_xlfn.MINIFS(Prices!$Y$2:$Y$106,Prices!$A$2:$A$106,$A31,Prices!$L$2:$L$106,"Y",Prices!$Y$2:$Y$106,">0") -> 0.462 | K31: =IFERROR(INDEX(Prices!$B$2:$B$106,MATCH($A31&"|"&TEXT($H31,"0.0000")&"|Y",Prices!$Z$2:$Z$106,0)),"none") -> Mouser Australia | L31: =IFERROR(INDEX(Prices!$B$2:$B$106,MATCH($A31&"|"&TEXT($J31,"0.0000")&"|Y",Prices!$AA$2:$AA$106,0)),"none") -> Mouser Australia | M31: =IF($G31=0,"NO PRICE",IF($G31=1,"Single source",""))
A32: RN8 | B32: Resistors | C32: Resistor network SIP-9 bussed 8 × 10 kΩ | E32: 4 | F32: Bus, Front panel | G32: =COUNTIFS(Prices!$A$2:$A$106,$A32,Prices!$L$2:$L$106,"Y",Prices!$E$2:$E$106,">0") -> 2 | H32: =_xlfn.MINIFS(Prices!$W$2:$W$106,Prices!$A$2:$A$106,$A32,Prices!$L$2:$L$106,"Y",Prices!$W$2:$W$106,">0") -> 2.4904 | I32: =_xlfn.MINIFS(Prices!$X$2:$X$106,Prices!$A$2:$A$106,$A32,Prices!$L$2:$L$106,"Y",Prices!$X$2:$X$106,">0") -> 1.5884 | J32: =_xlfn.MINIFS(Prices!$Y$2:$Y$106,Prices!$A$2:$A$106,$A32,Prices!$L$2:$L$106,"Y",Prices!$Y$2:$Y$106,">0") -> 0.902 | K32: =IFERROR(INDEX(Prices!$B$2:$B$106,MATCH($A32&"|"&TEXT($H32,"0.0000")&"|Y",Prices!$Z$2:$Z$106,0)),"none") -> Mouser Australia | L32: =IFERROR(INDEX(Prices!$B$2:$B$106,MATCH($A32&"|"&TEXT($J32,"0.0000")&"|Y",Prices!$AA$2:$AA$106,0)),"none") -> element14 Australia | M32: =IF($G32=0,"NO PRICE",IF($G32=1,"Single source",""))
A33: RN4 | B33: Resistors | C33: Resistor network SIP-5 bussed 4 × 10 kΩ | E33: 1 | F33: Front panel | G33: =COUNTIFS(Prices!$A$2:$A$106,$A33,Prices!$L$2:$L$106,"Y",Prices!$E$2:$E$106,">0") -> 2 | H33: =_xlfn.MINIFS(Prices!$W$2:$W$106,Prices!$A$2:$A$106,$A33,Prices!$L$2:$L$106,"Y",Prices!$W$2:$W$106,">0") -> 0.4477 | I33: =_xlfn.MINIFS(Prices!$X$2:$X$106,Prices!$A$2:$A$106,$A33,Prices!$L$2:$L$106,"Y",Prices!$X$2:$X$106,">0") -> 0.3377 | J33: =_xlfn.MINIFS(Prices!$Y$2:$Y$106,Prices!$A$2:$A$106,$A33,Prices!$L$2:$L$106,"Y",Prices!$Y$2:$Y$106,">0") -> 0.1683 | K33: =IFERROR(INDEX(Prices!$B$2:$B$106,MATCH($A33&"|"&TEXT($H33,"0.0000")&"|Y",Prices!$Z$2:$Z$106,0)),"none") -> element14 Australia | L33: =IFERROR(INDEX(Prices!$B$2:$B$106,MATCH($A33&"|"&TEXT($J33,"0.0000")&"|Y",Prices!$AA$2:$AA$106,0)),"none") -> element14 Australia | M33: =IF($G33=0,"NO PRICE",IF($G33=1,"Single source",""))
A34: C01 | B34: Capacitors | C34: Capacitor 100 nF ceramic | D34: 48 decoupling + 2 timing + 3 programmer + spares | E34: 60 | F34: All boards | G34: =COUNTIFS(Prices!$A$2:$A$106,$A34,Prices!$L$2:$L$106,"Y",Prices!$E$2:$E$106,">0") -> 2 | H34: =_xlfn.MINIFS(Prices!$W$2:$W$106,Prices!$A$2:$A$106,$A34,Prices!$L$2:$L$106,"Y",Prices!$W$2:$W$106,">0") -> 11.95 | I34: =_xlfn.MINIFS(Prices!$X$2:$X$106,Prices!$A$2:$A$106,$A34,Prices!$L$2:$L$106,"Y",Prices!$X$2:$X$106,">0") -> 7.17 | J34: =_xlfn.MINIFS(Prices!$Y$2:$Y$106,Prices!$A$2:$A$106,$A34,Prices!$L$2:$L$106,"Y",Prices!$Y$2:$Y$106,">0") -> 4.77 | K34: =IFERROR(INDEX(Prices!$B$2:$B$106,MATCH($A34&"|"&TEXT($H34,"0.0000")&"|Y",Prices!$Z$2:$Z$106,0)),"none") -> Jaycar | L34: =IFERROR(INDEX(Prices!$B$2:$B$106,MATCH($A34&"|"&TEXT($J34,"0.0000")&"|Y",Prices!$AA$2:$AA$106,0)),"none") -> Jaycar | M34: =IF($G34=0,"NO PRICE",IF($G34=1,"Single source",""))
A35: C10n | B35: Capacitors | C35: Capacitor 10 nF ceramic | D35: 555 control pins (4), RESET line filter (1) | E35: 5 | F35: Clock, Display driver, Front panel | G35: =COUNTIFS(Prices!$A$2:$A$106,$A35,Prices!$L$2:$L$106,"Y",Prices!$E$2:$E$106,">0") -> 2 | H35: =_xlfn.MINIFS(Prices!$W$2:$W$106,Prices!$A$2:$A$106,$A35,Prices!$L$2:$L$106,"Y",Prices!$W$2:$W$106,">0") -> 1.3035 | I35: =_xlfn.MINIFS(Prices!$X$2:$X$106,Prices!$A$2:$A$106,$A35,Prices!$L$2:$L$106,"Y",Prices!$X$2:$X$106,">0") -> 0.814 | J35: =_xlfn.MINIFS(Prices!$Y$2:$Y$106,Prices!$A$2:$A$106,$A35,Prices!$L$2:$L$106,"Y",Prices!$Y$2:$Y$106,">0") -> 0.7205 | K35: =IFERROR(INDEX(Prices!$B$2:$B$106,MATCH($A35&"|"&TEXT($H35,"0.0000")&"|Y",Prices!$Z$2:$Z$106,0)),"none") -> element14 Australia | L35: =IFERROR(INDEX(Prices!$B$2:$B$106,MATCH($A35&"|"&TEXT($J35,"0.0000")&"|Y",Prices!$AA$2:$AA$106,0)),"none") -> Mouser Australia | M35: =IF($G35=0,"NO PRICE",IF($G35=1,"Single source",""))
A36: C02 | B36: Capacitors | C36: Capacitor 1 µF electrolytic | E36: 2 | F36: Clock | G36: =COUNTIFS(Prices!$A$2:$A$106,$A36,Prices!$L$2:$L$106,"Y",Prices!$E$2:$E$106,">0") -> 2 | H36: =_xlfn.MINIFS(Prices!$W$2:$W$106,Prices!$A$2:$A$106,$A36,Prices!$L$2:$L$106,"Y",Prices!$W$2:$W$106,">0") -> 0.6 | I36: =_xlfn.MINIFS(Prices!$X$2:$X$106,Prices!$A$2:$A$106,$A36,Prices!$L$2:$L$106,"Y",Prices!$X$2:$X$106,">0") -> 0.6 | J36: =_xlfn.MINIFS(Prices!$Y$2:$Y$106,Prices!$A$2:$A$106,$A36,Prices!$L$2:$L$106,"Y",Prices!$Y$2:$Y$106,">0") -> 0.594 | K36: =IFERROR(INDEX(Prices!$B$2:$B$106,MATCH($A36&"|"&TEXT($H36,"0.0000")&"|Y",Prices!$Z$2:$Z$106,0)),"none") -> Jaycar | L36: =IFERROR(INDEX(Prices!$B$2:$B$106,MATCH($A36&"|"&TEXT($J36,"0.0000")&"|Y",Prices!$AA$2:$AA$106,0)),"none") -> Core Electronics | M36: =IF($G36=0,"NO PRICE",IF($G36=1,"Single source",""))
A37: C10u | B37: Capacitors | C37: Capacitor 10 µF electrolytic, 16 V or more | D37: bulk supply capacitor, one per board | E37: 16 | F37: every board except Bus | G37: =COUNTIFS(Prices!$A$2:$A$106,$A37,Prices!$L$2:$L$106,"Y",Prices!$E$2:$E$106,">0") -> 2 | H37: =_xlfn.MINIFS(Prices!$W$2:$W$106,Prices!$A$2:$A$106,$A37,Prices!$L$2:$L$106,"Y",Prices!$W$2:$W$106,">0") -> 4.8 | I37: =_xlfn.MINIFS(Prices!$X$2:$X$106,Prices!$A$2:$A$106,$A37,Prices!$L$2:$L$106,"Y",Prices!$X$2:$X$106,">0") -> 4.8 | J37: =_xlfn.MINIFS(Prices!$Y$2:$Y$106,Prices!$A$2:$A$106,$A37,Prices!$L$2:$L$106,"Y",Prices!$Y$2:$Y$106,">0") -> 4.8 | K37: =IFERROR(INDEX(Prices!$B$2:$B$106,MATCH($A37&"|"&TEXT($H37,"0.0000")&"|Y",Prices!$Z$2:$Z$106,0)),"none") -> Jaycar | L37: =IFERROR(INDEX(Prices!$B$2:$B$106,MATCH($A37&"|"&TEXT($J37,"0.0000")&"|Y",Prices!$AA$2:$AA$106,0)),"none") -> Jaycar | M37: =IF($G37=0,"NO PRICE",IF($G37=1,"Single source",""))
A38: C100u | B38: Capacitors | C38: Capacitor 100 µF electrolytic, 16 V or more | D38: bulk capacitor at the power entry | E38: 1 | F38: Bus | G38: =COUNTIFS(Prices!$A$2:$A$106,$A38,Prices!$L$2:$L$106,"Y",Prices!$E$2:$E$106,">0") -> 2 | H38: =_xlfn.MINIFS(Prices!$W$2:$W$106,Prices!$A$2:$A$106,$A38,Prices!$L$2:$L$106,"Y",Prices!$W$2:$W$106,">0") -> 0.275 | I38: =_xlfn.MINIFS(Prices!$X$2:$X$106,Prices!$A$2:$A$106,$A38,Prices!$L$2:$L$106,"Y",Prices!$X$2:$X$106,">0") -> 0.275 | J38: =_xlfn.MINIFS(Prices!$Y$2:$Y$106,Prices!$A$2:$A$106,$A38,Prices!$L$2:$L$106,"Y",Prices!$Y$2:$Y$106,">0") -> 0.264 | K38: =IFERROR(INDEX(Prices!$B$2:$B$106,MATCH($A38&"|"&TEXT($H38,"0.0000")&"|Y",Prices!$Z$2:$Z$106,0)),"none") -> Core Electronics | L38: =IFERROR(INDEX(Prices!$B$2:$B$106,MATCH($A38&"|"&TEXT($J38,"0.0000")&"|Y",Prices!$AA$2:$AA$106,0)),"none") -> Core Electronics | M38: =IF($G38=0,"NO PRICE",IF($G38=1,"Single source",""))
A39: VR1 | B39: Controls | C39: Potentiometer 1 MΩ linear | D39: clock speed | E39: 1 | F39: Clock | G39: =COUNTIFS(Prices!$A$2:$A$106,$A39,Prices!$L$2:$L$106,"Y",Prices!$E$2:$E$106,">0") -> 2 | H39: =_xlfn.MINIFS(Prices!$W$2:$W$106,Prices!$A$2:$A$106,$A39,Prices!$L$2:$L$106,"Y",Prices!$W$2:$W$106,">0") -> 2.9 | I39: =_xlfn.MINIFS(Prices!$X$2:$X$106,Prices!$A$2:$A$106,$A39,Prices!$L$2:$L$106,"Y",Prices!$X$2:$X$106,">0") -> 2.35 | J39: =_xlfn.MINIFS(Prices!$Y$2:$Y$106,Prices!$A$2:$A$106,$A39,Prices!$L$2:$L$106,"Y",Prices!$Y$2:$Y$106,">0") -> 2.35 | K39: =IFERROR(INDEX(Prices!$B$2:$B$106,MATCH($A39&"|"&TEXT($H39,"0.0000")&"|Y",Prices!$Z$2:$Z$106,0)),"none") -> Altronics | L39: =IFERROR(INDEX(Prices!$B$2:$B$106,MATCH($A39&"|"&TEXT($J39,"0.0000")&"|Y",Prices!$AA$2:$AA$106,0)),"none") -> Altronics | M39: =IF($G39=0,"NO PRICE",IF($G39=1,"Single source",""))
A40: JP3 | B40: Controls | C40: 3-pin header + jumper shunt | D40: clock range | E40: 1 | F40: Clock | G40: =COUNTIFS(Prices!$A$2:$A$106,$A40,Prices!$L$2:$L$106,"Y",Prices!$E$2:$E$106,">0") -> 2 | H40: =_xlfn.MINIFS(Prices!$W$2:$W$106,Prices!$A$2:$A$106,$A40,Prices!$L$2:$L$106,"Y",Prices!$W$2:$W$106,">0") -> 1.0373 | I40: =_xlfn.MINIFS(Prices!$X$2:$X$106,Prices!$A$2:$A$106,$A40,Prices!$L$2:$L$106,"Y",Prices!$X$2:$X$106,">0") -> 0.8965 | J40: =_xlfn.MINIFS(Prices!$Y$2:$Y$106,Prices!$A$2:$A$106,$A40,Prices!$L$2:$L$106,"Y",Prices!$Y$2:$Y$106,">0") -> 0.715 | K40: =IFERROR(INDEX(Prices!$B$2:$B$106,MATCH($A40&"|"&TEXT($H40,"0.0000")&"|Y",Prices!$Z$2:$Z$106,0)),"none") -> Mouser Australia | L40: =IFERROR(INDEX(Prices!$B$2:$B$106,MATCH($A40&"|"&TEXT($J40,"0.0000")&"|Y",Prices!$AA$2:$AA$106,0)),"none") -> Mouser Australia | M40: =IF($G40=0,"NO PRICE",IF($G40=1,"Single source",""))
A41: SW1 | B41: Switches | C41: Tactile push button 6 mm | D41: STEP, RESET, WRITE | E41: 3 | F41: Front panel | G41: =COUNTIFS(Prices!$A$2:$A$106,$A41,Prices!$L$2:$L$106,"Y",Prices!$E$2:$E$106,">0") -> 2 | H41: =_xlfn.MINIFS(Prices!$W$2:$W$106,Prices!$A$2:$A$106,$A41,Prices!$L$2:$L$106,"Y",Prices!$W$2:$W$106,">0") -> 2.85 | I41: =_xlfn.MINIFS(Prices!$X$2:$X$106,Prices!$A$2:$A$106,$A41,Prices!$L$2:$L$106,"Y",Prices!$X$2:$X$106,">0") -> 0.979 | J41: =_xlfn.MINIFS(Prices!$Y$2:$Y$106,Prices!$A$2:$A$106,$A41,Prices!$L$2:$L$106,"Y",Prices!$Y$2:$Y$106,">0") -> 0.7128 | K41: =IFERROR(INDEX(Prices!$B$2:$B$106,MATCH($A41&"|"&TEXT($H41,"0.0000")&"|Y",Prices!$Z$2:$Z$106,0)),"none") -> Jaycar | L41: =IFERROR(INDEX(Prices!$B$2:$B$106,MATCH($A41&"|"&TEXT($J41,"0.0000")&"|Y",Prices!$AA$2:$AA$106,0)),"none") -> Core Electronics | M41: =IF($G41=0,"NO PRICE",IF($G41=1,"Single source",""))
A42: SW2 | B42: Switches | C42: Slide switch SPDT, 0.1 in pitch | D42: RUN/STEP, PROGRAM/RUN; PROGRAM/RUN is wired as on/off to +5 V with a 10 kΩ pull-down, so a shorting (make-before-break) switch is safe too | E42: 2 | F42: Front panel | G42: =COUNTIFS(Prices!$A$2:$A$106,$A42,Prices!$L$2:$L$106,"Y",Prices!$E$2:$E$106,">0") -> 2 | H42: =_xlfn.MINIFS(Prices!$W$2:$W$106,Prices!$A$2:$A$106,$A42,Prices!$L$2:$L$106,"Y",Prices!$W$2:$W$106,">0") -> 3.806 | I42: =_xlfn.MINIFS(Prices!$X$2:$X$106,Prices!$A$2:$A$106,$A42,Prices!$L$2:$L$106,"Y",Prices!$X$2:$X$106,">0") -> 3.6 | J42: =_xlfn.MINIFS(Prices!$Y$2:$Y$106,Prices!$A$2:$A$106,$A42,Prices!$L$2:$L$106,"Y",Prices!$Y$2:$Y$106,">0") -> 3.2 | K42: =IFERROR(INDEX(Prices!$B$2:$B$106,MATCH($A42&"|"&TEXT($H42,"0.0000")&"|Y",Prices!$Z$2:$Z$106,0)),"none") -> Core Electronics | L42: =IFERROR(INDEX(Prices!$B$2:$B$106,MATCH($A42&"|"&TEXT($J42,"0.0000")&"|Y",Prices!$AA$2:$AA$106,0)),"none") -> Jaycar | M42: =IF($G42=0,"NO PRICE",IF($G42=1,"Single source",""))
A43: SW3 | B43: Switches | C43: DIP switch 8-position | D43: data, input A, input B | E43: 3 | F43: Front panel | G43: =COUNTIFS(Prices!$A$2:$A$106,$A43,Prices!$L$2:$L$106,"Y",Prices!$E$2:$E$106,">0") -> 2 | H43: =_xlfn.MINIFS(Prices!$W$2:$W$106,Prices!$A$2:$A$106,$A43,Prices!$L$2:$L$106,"Y",Prices!$W$2:$W$106,">0") -> 10.8 | I43: =_xlfn.MINIFS(Prices!$X$2:$X$106,Prices!$A$2:$A$106,$A43,Prices!$L$2:$L$106,"Y",Prices!$X$2:$X$106,">0") -> 10.758 | J43: =_xlfn.MINIFS(Prices!$Y$2:$Y$106,Prices!$A$2:$A$106,$A43,Prices!$L$2:$L$106,"Y",Prices!$Y$2:$Y$106,">0") -> 10.098 | K43: =IFERROR(INDEX(Prices!$B$2:$B$106,MATCH($A43&"|"&TEXT($H43,"0.0000")&"|Y",Prices!$Z$2:$Z$106,0)),"none") -> Jaycar | L43: =IFERROR(INDEX(Prices!$B$2:$B$106,MATCH($A43&"|"&TEXT($J43,"0.0000")&"|Y",Prices!$AA$2:$AA$106,0)),"none") -> Core Electronics | M43: =IF($G43=0,"NO PRICE",IF($G43=1,"Single source",""))
A44: SW4 | B44: Switches | C44: DIP switch 4-position | D44: address | E44: 1 | F44: Front panel | G44: =COUNTIFS(Prices!$A$2:$A$106,$A44,Prices!$L$2:$L$106,"Y",Prices!$E$2:$E$106,">0") -> 2 | H44: =_xlfn.MINIFS(Prices!$W$2:$W$106,Prices!$A$2:$A$106,$A44,Prices!$L$2:$L$106,"Y",Prices!$W$2:$W$106,">0") -> 1.9 | I44: =_xlfn.MINIFS(Prices!$X$2:$X$106,Prices!$A$2:$A$106,$A44,Prices!$L$2:$L$106,"Y",Prices!$X$2:$X$106,">0") -> 1.65 | J44: =_xlfn.MINIFS(Prices!$Y$2:$Y$106,Prices!$A$2:$A$106,$A44,Prices!$L$2:$L$106,"Y",Prices!$Y$2:$Y$106,">0") -> 1.5 | K44: =IFERROR(INDEX(Prices!$B$2:$B$106,MATCH($A44&"|"&TEXT($H44,"0.0000")&"|Y",Prices!$Z$2:$Z$106,0)),"none") -> Wiltronics | L44: =IFERROR(INDEX(Prices!$B$2:$B$106,MATCH($A44&"|"&TEXT($J44,"0.0000")&"|Y",Prices!$AA$2:$AA$106,0)),"none") -> Wiltronics | M44: =IF($G44=0,"NO PRICE",IF($G44=1,"Single source",""))
A45: BB01 | B45: Build | C45: Solderless breadboard 830 tie-point | D45: 17 for PC-2 + 1 programmer | E45: 18 | F45: All | G45: =COUNTIFS(Prices!$A$2:$A$106,$A45,Prices!$L$2:$L$106,"Y",Prices!$E$2:$E$106,">0") -> 2 | H45: =_xlfn.MINIFS(Prices!$W$2:$W$106,Prices!$A$2:$A$106,$A45,Prices!$L$2:$L$106,"Y",Prices!$W$2:$W$106,">0") -> 71.082 | I45: =_xlfn.MINIFS(Prices!$X$2:$X$106,Prices!$A$2:$A$106,$A45,Prices!$L$2:$L$106,"Y",Prices!$X$2:$X$106,">0") -> 60.39 | J45: =_xlfn.MINIFS(Prices!$Y$2:$Y$106,Prices!$A$2:$A$106,$A45,Prices!$L$2:$L$106,"Y",Prices!$Y$2:$Y$106,">0") -> 60.39 | K45: =IFERROR(INDEX(Prices!$B$2:$B$106,MATCH($A45&"|"&TEXT($H45,"0.0000")&"|Y",Prices!$Z$2:$Z$106,0)),"none") -> Core Electronics | L45: =IFERROR(INDEX(Prices!$B$2:$B$106,MATCH($A45&"|"&TEXT($J45,"0.0000")&"|Y",Prices!$AA$2:$AA$106,0)),"none") -> Core Electronics | M45: =IF($G45=0,"NO PRICE",IF($G45=1,"Single source",""))
A46: W01 | B46: Build | C46: 22 AWG solid-core hook-up wire, 6-colour set (red, black, yellow, blue, green, white) | D46: 3 boxes = 137 m; with W02-W04 covers the about 91 m used (25 m on the boards, 66 m between boards). White is used for the clock (drawn pink) | E46: 3 | F46: All | G46: =COUNTIFS(Prices!$A$2:$A$106,$A46,Prices!$L$2:$L$106,"Y",Prices!$E$2:$E$106,">0") -> 1 | H46: =_xlfn.MINIFS(Prices!$W$2:$W$106,Prices!$A$2:$A$106,$A46,Prices!$L$2:$L$106,"Y",Prices!$W$2:$W$106,">0") -> 161.403 | I46: =_xlfn.MINIFS(Prices!$X$2:$X$106,Prices!$A$2:$A$106,$A46,Prices!$L$2:$L$106,"Y",Prices!$X$2:$X$106,">0") -> 156.585 | J46: =_xlfn.MINIFS(Prices!$Y$2:$Y$106,Prices!$A$2:$A$106,$A46,Prices!$L$2:$L$106,"Y",Prices!$Y$2:$Y$106,">0") -> 146.883 | K46: =IFERROR(INDEX(Prices!$B$2:$B$106,MATCH($A46&"|"&TEXT($H46,"0.0000")&"|Y",Prices!$Z$2:$Z$106,0)),"none") -> Core Electronics | L46: =IFERROR(INDEX(Prices!$B$2:$B$106,MATCH($A46&"|"&TEXT($J46,"0.0000")&"|Y",Prices!$AA$2:$AA$106,0)),"none") -> Core Electronics | M46: =IF($G46=0,"NO PRICE",IF($G46=1,"Single source","")) -> Single source
A47: W02 | B47: Build | C47: 22 AWG solid-core wire, orange, 25 ft (7.6 m) spool | D47: reset and mode wires (about 3.8 m) | E47: 1 | F47: Clock, Front panel, Output and others | G47: =COUNTIFS(Prices!$A$2:$A$106,$A47,Prices!$L$2:$L$106,"Y",Prices!$E$2:$E$106,">0") -> 1 | H47: =_xlfn.MINIFS(Prices!$W$2:$W$106,Prices!$A$2:$A$106,$A47,Prices!$L$2:$L$106,"Y",Prices!$W$2:$W$106,">0") -> 10.197 | I47: =_xlfn.MINIFS(Prices!$X$2:$X$106,Prices!$A$2:$A$106,$A47,Prices!$L$2:$L$106,"Y",Prices!$X$2:$X$106,">0") -> 9.889 | J47: =_xlfn.MINIFS(Prices!$Y$2:$Y$106,Prices!$A$2:$A$106,$A47,Prices!$L$2:$L$106,"Y",Prices!$Y$2:$Y$106,">0") -> 9.691 | K47: =IFERROR(INDEX(Prices!$B$2:$B$106,MATCH($A47&"|"&TEXT($H47,"0.0000")&"|Y",Prices!$Z$2:$Z$106,0)),"none") -> Core Electronics | L47: =IFERROR(INDEX(Prices!$B$2:$B$106,MATCH($A47&"|"&TEXT($J47,"0.0000")&"|Y",Prices!$AA$2:$AA$106,0)),"none") -> Core Electronics | M47: =IF($G47=0,"NO PRICE",IF($G47=1,"Single source","")) -> Single source
A48: W03 | B48: Build | C48: 22 AWG solid-core wire, purple (m) | D48: addresses and step numbers (about 4.7 m); cut from a 30 m reel | E48: 5 | F48: MAR, RAM, Control sequencer and others | G48: =COUNTIFS(Prices!$A$2:$A$106,$A48,Prices!$L$2:$L$106,"Y",Prices!$E$2:$E$106,">0") -> 1 | H48: =_xlfn.MINIFS(Prices!$W$2:$W$106,Prices!$A$2:$A$106,$A48,Prices!$L$2:$L$106,"Y",Prices!$W$2:$W$106,">0") -> 98.329 | I48: =_xlfn.MINIFS(Prices!$X$2:$X$106,Prices!$A$2:$A$106,$A48,Prices!$L$2:$L$106,"Y",Prices!$X$2:$X$106,">0") -> 19.6658 | J48: =_xlfn.MINIFS(Prices!$Y$2:$Y$106,Prices!$A$2:$A$106,$A48,Prices!$L$2:$L$106,"Y",Prices!$Y$2:$Y$106,">0") -> 16.71593 | K48: =IFERROR(INDEX(Prices!$B$2:$B$106,MATCH($A48&"|"&TEXT($H48,"0.0000")&"|Y",Prices!$Z$2:$Z$106,0)),"none") -> RS Components Australia | L48: =IFERROR(INDEX(Prices!$B$2:$B$106,MATCH($A48&"|"&TEXT($J48,"0.0000")&"|Y",Prices!$AA$2:$AA$106,0)),"none") -> RS Components Australia | M48: =IF($G48=0,"NO PRICE",IF($G48=1,"Single source","")) -> Single source
... A52: PSU | B52: Power | C52: USB-C 5 V 3 A power supply, RCM approved (Raspberry Pi 15 W) | D52: any RCM-marked USB-C supply giving 5 V at 2.5 A or more, so that F1 can trip on a short | E52: 1 | F52: Power | G52: =COUNTIFS(Prices!$A$2:$A$106,$A52,Prices!$L$2:$L$106,"Y",Prices!$E$2:$E$106,">0") -> 2 | H52: =_xlfn.MINIFS(Prices!$W$2:$W$106,Prices!$A$2:$A$106,$A52,Prices!$L$2:$L$106,"Y",Prices!$W$2:$W$106,">0") -> 11.9 | I52: =_xlfn.MINIFS(Prices!$X$2:$X$106,Prices!$A$2:$A$106,$A52,Prices!$L$2:$L$106,"Y",Prices!$X$2:$X$106,">0") -> 11.9 | J52: =_xlfn.MINIFS(Prices!$Y$2:$Y$106,Prices!$A$2:$A$106,$A52,Prices!$L$2:$L$106,"Y",Prices!$Y$2:$Y$106,">0") -> 11.9 | K52: =IFERROR(INDEX(Prices!$B$2:$B$106,MATCH($A52&"|"&TEXT($H52,"0.0000")&"|Y",Prices!$Z$2:$Z$106,0)),"none") -> Core Electronics | L52: =IFERROR(INDEX(Prices!$B$2:$B$106,MATCH($A52&"|"&TEXT($J52,"0.0000")&"|Y",Prices!$AA$2:$AA$106,0)),"none") -> Core Electronics | M52: =IF($G52=0,"NO PRICE",IF($G52=1,"Single source",""))
A53: PG01 | B53: Programmer | C53: Nano-compatible board (compatible with Arduino®; 5 V, ATmega328P) | E53: 1 | F53: EEPROM programmer | G53: =COUNTIFS(Prices!$A$2:$A$106,$A53,Prices!$L$2:$L$106,"Y",Prices!$E$2:$E$106,">0") -> 2 | H53: =_xlfn.MINIFS(Prices!$W$2:$W$106,Prices!$A$2:$A$106,$A53,Prices!$L$2:$L$106,"Y",Prices!$W$2:$W$106,">0") -> 6.545 | I53: =_xlfn.MINIFS(Prices!$X$2:$X$106,Prices!$A$2:$A$106,$A53,Prices!$L$2:$L$106,"Y",Prices!$X$2:$X$106,">0") -> 5.896 | J53: =_xlfn.MINIFS(Prices!$Y$2:$Y$106,Prices!$A$2:$A$106,$A53,Prices!$L$2:$L$106,"Y",Prices!$Y$2:$Y$106,">0") -> 5.566 | K53: =IFERROR(INDEX(Prices!$B$2:$B$106,MATCH($A53&"|"&TEXT($H53,"0.0000")&"|Y",Prices!$Z$2:$Z$106,0)),"none") -> Core Electronics | L53: =IFERROR(INDEX(Prices!$B$2:$B$106,MATCH($A53&"|"&TEXT($J53,"0.0000")&"|Y",Prices!$AA$2:$AA$106,0)),"none") -> Core Electronics | M53: =IF($G53=0,"NO PRICE",IF($G53=1,"Single source",""))
A54: PG02 | B54: Programmer | C54: 74HC595 | D54: 8-bit shift register, DIP-16 | E54: 2 | F54: EEPROM programmer | G54: =COUNTIFS(Prices!$A$2:$A$106,$A54,Prices!$L$2:$L$106,"Y",Prices!$E$2:$E$106,">0") -> 2 | H54: =_xlfn.MINIFS(Prices!$W$2:$W$106,Prices!$A$2:$A$106,$A54,Prices!$L$2:$L$106,"Y",Prices!$W$2:$W$106,">0") -> 3.6 | I54: =_xlfn.MINIFS(Prices!$X$2:$X$106,Prices!$A$2:$A$106,$A54,Prices!$L$2:$L$106,"Y",Prices!$X$2:$X$106,">0") -> 3.6 | J54: =_xlfn.MINIFS(Prices!$Y$2:$Y$106,Prices!$A$2:$A$106,$A54,Prices!$L$2:$L$106,"Y",Prices!$Y$2:$Y$106,">0") -> 3.6 | K54: =IFERROR(INDEX(Prices!$B$2:$B$106,MATCH($A54&"|"&TEXT($H54,"0.0000")&"|Y",Prices!$Z$2:$Z$106,0)),"none") -> Core Electronics | L54: =IFERROR(INDEX(Prices!$B$2:$B$106,MATCH($A54&"|"&TEXT($J54,"0.0000")&"|Y",Prices!$AA$2:$AA$106,0)),"none") -> Core Electronics | M54: =IF($G54=0,"NO PRICE",IF($G54=1,"Single source",""))
A55: Total parts cost per kit (AUD incl GST) | H55: =SUM(H2:H54) -> 655.3066 | I55: =SUM(I2:I54) -> 509.5845 | J55: =SUM(J2:J54) -> 478.27793
A56: Chips per kit (IC lines, excluding programmer) | E56: =SUMIFS(E2:E54,A2:A54,"IC*") -> 9

Sheet Prices
A1: ID | B1: Supplier | C1: Part / SKU | D1: Pack size | E1: Price q1 (AUD) | F1: Break 2 qty | G1: Break 2 price | H1: Break 3 qty | I1: Break 3 price | J1: Price incl GST? | K1: Stock shown | L1: Suitable | M1: Checked | N1: URL | O1: Note | P1: Qty per kit | Q1: Packs @T1 | R1: Packs @T2 | S1: Packs @T3 | T1: Pack price incl GST @T1 | U1: @T2 | V1: @T3 | W1: Cost per kit @T1 | X1: Cost per kit @T2 | Y1: Cost per kit @T3 | Z1: Key T1 | AA1: Key T3
A2: H00 | B2: Mouser Australia | C2: CD74HCT00E (595-CD74HCT00E) | D2: 1 | E2: 1.15 | F2: 10 | G2: 0.821 | H2: 100 | I2: 0.647 | J2: N | K2: 590 | L2: Y | M2: 2026-10-25 | N2: https://au.mouser.com/c/?q=CD74HCT00E | O2: Mouser page states no GST treatment; treated as ex GST. TI PDIP-14 tube. | P2: =IFERROR(VLOOKUP($A2,BOM!$A$2:$E$54,5,0),0) -> 1 | Q2: =CEILING($P2*Assumptions!$B$4/$D2,1) -> 1 | R2: =CEILING($P2*Assumptions!$B$5/$D2,1) -> 10 | S2: =CEILING($P2*Assumptions!$B$6/$D2,1) -> 100 | T2: =IF(ISNUMBER($E2),IF(AND(ISNUMBER($I2),ISNUMBER($H2)),IF($H2<=$Q2,$I2,IF(AND(ISNUMBER($G2),ISNUMBER($F2)),IF($F2<=$Q2,$G2,$E2),$E2)),IF(AND(ISNUMBER($G2),ISNUMBER($F2)),IF($F2<=$Q2,$G2,$E2),$E2))*(1+IF($J2="Y",0,Assumptions!$B$3)),"") -> 1.265 | U2: =IF(ISNUMBER($E2),IF(AND(ISNUMBER($I2),ISNUMBER($H2)),IF($H2<=$R2,$I2,IF(AND(ISNUMBER($G2),ISNUMBER($F2)),IF($F2<=$R2,$G2,$E2),$E2)),IF(AND(ISNUMBER($G2),ISNUMBER($F2)),IF($F2<=$R2,$G2,$E2),$E2))*(1+IF($J2="Y",0,Assumptions!$B$3)),"") -> 0.9031 | V2: =IF(ISNUMBER($E2),IF(AND(ISNUMBER($I2),ISNUMBER($H2)),IF($H2<=$S2,$I2,IF(AND(ISNUMBER($G2),ISNUMBER($F2)),IF($F2<=$S2,$G2,$E2),$E2)),IF(AND(ISNUMBER($G2),ISNUMBER($F2)),IF($F2<=$S2,$G2,$E2),$E2))*(1+IF($J2="Y",0,Assumptions!$B$3)),"") -> 0.7117 | W2: =IF(ISNUMBER($T2),$Q2*$T2/Assumptions!$B$4,"") -> 1.265 | X2: =IF(ISNUMBER($U2),$R2*$U2/Assumptions!$B$5,"") -> 0.9031 | Y2: =IF(ISNUMBER($V2),$S2*$V2/Assumptions!$B$6,"") -> 0.7117 | Z2: =$A2&"|"&IF(ISNUMBER($W2),TEXT($W2,"0.0000"),"x")&"|"&$L2 -> H00|1.2650|Y | AA2: =$A2&"|"&IF(ISNUMBER($Y2),TEXT($Y2,"0.0000"),"x")&"|"&$L2 -> H00|0.7117|Y
A3: H00 | B3: Wiltronics (AU) | C3: 74HCT00 | D3: 1 | E3: 1.95 | F3: 10 | G3: 1.7 | H3: 25 | I3: 1.6 | J3: Y | K3: not shown | L3: Y | M3: 2026-10-25 | N3: https://www.wiltronics.com.au/product/317/74hct00-quad-2-input-nand-gate-4/ | O3: Wiltronics states prices include GST; no stock indicator on page. Not on preferred list but Australian retailer. DIP-14; manufacturer not stated. Highest break shown is 25. element14 AU: no DIP 74HCT00 (SMD only). | P3: =IFERROR(VLOOKUP($A3,BOM!$A$2:$E$54,5,0),0) -> 1 | Q3: =CEILING($P3*Assumptions!$B$4/$D3,1) -> 1 | R3: =CEILING($P3*Assumptions!$B$5/$D3,1) -> 10 | S3: =CEILING($P3*Assumptions!$B$6/$D3,1) -> 100 | T3: =IF(ISNUMBER($E3),IF(AND(ISNUMBER($I3),ISNUMBER($H3)),IF($H3<=$Q3,$I3,IF(AND(ISNUMBER($G3),ISNUMBER($F3)),IF($F3<=$Q3,$G3,$E3),$E3)),IF(AND(ISNUMBER($G3),ISNUMBER($F3)),IF($F3<=$Q3,$G3,$E3),$E3))*(1+IF($J3="Y",0,Assumptions!$B$3)),"") -> 1.95 | U3: =IF(ISNUMBER($E3),IF(AND(ISNUMBER($I3),ISNUMBER($H3)),IF($H3<=$R3,$I3,IF(AND(ISNUMBER($G3),ISNUMBER($F3)),IF($F3<=$R3,$G3,$E3),$E3)),IF(AND(ISNUMBER($G3),ISNUMBER($F3)),IF($F3<=$R3,$G3,$E3),$E3))*(1+IF($J3="Y",0,Assumptions!$B$3)),"") -> 1.7 | V3: =IF(ISNUMBER($E3),IF(AND(ISNUMBER($I3),ISNUMBER($H3)),IF($H3<=$S3,$I3,IF(AND(ISNUMBER($G3),ISNUMBER($F3)),IF($F3<=$S3,$G3,$E3),$E3)),IF(AND(ISNUMBER($G3),ISNUMBER($F3)),IF($F3<=$S3,$G3,$E3),$E3))*(1+IF($J3="Y",0,Assumptions!$B$3)),"") -> 1.6 | W3: =IF(ISNUMBER($T3),$Q3*$T3/Assumptions!$B$4,"") -> 1.95 | X3: =IF(ISNUMBER($U3),$R3*$U3/Assumptions!$B$5,"") -> 1.7 | Y3: =IF(ISNUMBER($V3),$S3*$V3/Assumptions!$B$6,"") -> 1.6 | Z3: =$A3&"|"&IF(ISNUMBER($W3),TEXT($W3,"0.0000"),"x")&"|"&$L3 -> H00|1.9500|Y | AA3: =$A3&"|"&IF(ISNUMBER($Y3),TEXT($Y3,"0.0000"),"x")&"|"&$L3 -> H00|1.6000|Y
A4: H02 | B4: Mouser Australia | C4: CD74HCT02E (595-CD74HCT02E) | D4: 1 | E4: 1.06 | F4: 10 | G4: 0.754 | H4: 100 | I4: 0.597 | J4: N | K4: 2054 | L4: Y | M4: 2026-10-25 | N4: https://au.mouser.com/c/?q=CD74HCT02E | O4: Mouser page states no GST treatment; treated as ex GST. TI PDIP-14. | P4: =IFERROR(VLOOKUP($A4,BOM!$A$2:$E$54,5,0),0) -> 1 | Q4: =CEILING($P4*Assumptions!$B$4/$D4,1) -> 1 | R4: =CEILING($P4*Assumptions!$B$5/$D4,1) -> 10 | S4: =CEILING($P4*Assumptions!$B$6/$D4,1) -> 100 | T4: =IF(ISNUMBER($E4),IF(AND(ISNUMBER($I4),ISNUMBER($H4)),IF($H4<=$Q4,$I4,IF(AND(ISNUMBER($G4),ISNUMBER($F4)),IF($F4<=$Q4,$G4,$E4),$E4)),IF(AND(ISNUMBER($G4),ISNUMBER($F4)),IF($F4<=$Q4,$G4,$E4),$E4))*(1+IF($J4="Y",0,Assumptions!$B$3)),"") -> 1.166 | U4: =IF(ISNUMBER($E4),IF(AND(ISNUMBER($I4),ISNUMBER($H4)),IF($H4<=$R4,$I4,IF(AND(ISNUMBER($G4),ISNUMBER($F4)),IF($F4<=$R4,$G4,$E4),$E4)),IF(AND(ISNUMBER($G4),ISNUMBER($F4)),IF($F4<=$R4,$G4,$E4),$E4))*(1+IF($J4="Y",0,Assumptions!$B$3)),"") -> 0.8294 | V4: =IF(ISNUMBER($E4),IF(AND(ISNUMBER($I4),ISNUMBER($H4)),IF($H4<=$S4,$I4,IF(AND(ISNUMBER($G4),ISNUMBER($F4)),IF($F4<=$S4,$G4,$E4),$E4)),IF(AND(ISNUMBER($G4),ISNUMBER($F4)),IF($F4<=$S4,$G4,$E4),$E4))*(1+IF($J4="Y",0,Assumptions!$B$3)),"") -> 0.6567 | W4: =IF(ISNUMBER($T4),$Q4*$T4/Assumptions!$B$4,"") -> 1.166 | X4: =IF(ISNUMBER($U4),$R4*$U4/Assumptions!$B$5,"") -> 0.8294 | Y4: =IF(ISNUMBER($V4),$S4*$V4/Assumptions!$B$6,"") -> 0.6567 | Z4: =$A4&"|"&IF(ISNUMBER($W4),TEXT($W4,"0.0000"),"x")&"|"&$L4 -> H02|1.1660|Y | AA4: =$A4&"|"&IF(ISNUMBER($Y4),TEXT($Y4,"0.0000"),"x")&"|"&$L4 -> H02|0.6567|Y
A5: H02 | B5: Wiltronics (AU) | C5: 74HCT02 | D5: 1 | E5: 0.55 | F5: 10 | G5: 0.5 | H5: 25 | I5: 0.45 | J5: Y | K5: not shown | L5: Y | M5: 2026-10-25 | N5: https://www.wiltronics.com.au/product/3759/74hct02-quad-2-input-positive-nor-gate/ | O5: Wiltronics states prices include GST; no stock indicator on page. Not on preferred list but Australian retailer. DIP-14; manufacturer not stated. element14 AU: no exact match for CD74HCT02E/SN74HCT02N. | P5: =IFERROR(VLOOKUP($A5,BOM!$A$2:$E$54,5,0),0) -> 1 | Q5: =CEILING($P5*Assumptions!$B$4/$D5,1) -> 1 | R5: =CEILING($P5*Assumptions!$B$5/$D5,1) -> 10 | S5: =CEILING($P5*Assumptions!$B$6/$D5,1) -> 100 | T5: =IF(ISNUMBER($E5),IF(AND(ISNUMBER($I5),ISNUMBER($H5)),IF($H5<=$Q5,$I5,IF(AND(ISNUMBER($G5),ISNUMBER($F5)),IF($F5<=$Q5,$G5,$E5),$E5)),IF(AND(ISNUMBER($G5),ISNUMBER($F5)),IF($F5<=$Q5,$G5,$E5),$E5))*(1+IF($J5="Y",0,Assumptions!$B$3)),"") -> 0.55 | U5: =IF(ISNUMBER($E5),IF(AND(ISNUMBER($I5),ISNUMBER($H5)),IF($H5<=$R5,$I5,IF(AND(ISNUMBER($G5),ISNUMBER($F5)),IF($F5<=$R5,$G5,$E5),$E5)),IF(AND(ISNUMBER($G5),ISNUMBER($F5)),IF($F5<=$R5,$G5,$E5),$E5))*(1+IF($J5="Y",0,Assumptions!$B$3)),"") -> 0.5 | V5: =IF(ISNUMBER($E5),IF(AND(ISNUMBER($I5),ISNUMBER($H5)),IF($H5<=$S5,$I5,IF(AND(ISNUMBER($G5),ISNUMBER($F5)),IF($F5<=$S5,$G5,$E5),$E5)),IF(AND(ISNUMBER($G5),ISNUMBER($F5)),IF($F5<=$S5,$G5,$E5),$E5))*(1+IF($J5="Y",0,Assumptions!$B$3)),"") -> 0.45 | W5: =IF(ISNUMBER($T5),$Q5*$T5/Assumptions!$B$4,"") -> 0.55 | X5: =IF(ISNUMBER($U5),$R5*$U5/Assumptions!$B$5,"") -> 0.5 | Y5: =IF(ISNUMBER($V5),$S5*$V5/Assumptions!$B$6,"") -> 0.45 | Z5: =$A5&"|"&IF(ISNUMBER($W5),TEXT($W5,"0.0000"),"x")&"|"&$L5 -> H02|0.5500|Y | AA5: =$A5&"|"&IF(ISNUMBER($Y5),TEXT($Y5,"0.0000"),"x")&"|"&$L5 -> H02|0.4500|Y
A6: H04 | B6: Mouser Australia | C6: CD74HCT04E (595-CD74HCT04E) | D6: 1 | E6: 1.33 | F6: 10 | G6: 0.961 | H6: 100 | I6: 0.769 | J6: N | K6: 3913 | L6: Y | M6: 2026-10-25 | N6: https://au.mouser.com/c/?q=CD74HCT04E | O6: Mouser page states no GST treatment; treated as ex GST. TI PDIP-14. | P6: =IFERROR(VLOOKUP($A6,BOM!$A$2:$E$54,5,0),0) -> 2 | Q6: =CEILING($P6*Assumptions!$B$4/$D6,1) -> 2 | R6: =CEILING($P6*Assumptions!$B$5/$D6,1) -> 20 | S6: =CEILING($P6*Assumptions!$B$6/$D6,1) -> 200 | T6: =IF(ISNUMBER($E6),IF(AND(ISNUMBER($I6),ISNUMBER($H6)),IF($H6<=$Q6,$I6,IF(AND(ISNUMBER($G6),ISNUMBER($F6)),IF($F6<=$Q6,$G6,$E6),$E6)),IF(AND(ISNUMBER($G6),ISNUMBER($F6)),IF($F6<=$Q6,$G6,$E6),$E6))*(1+IF($J6="Y",0,Assumptions!$B$3)),"") -> 1.463 | U6: =IF(ISNUMBER($E6),IF(AND(ISNUMBER($I6),ISNUMBER($H6)),IF($H6<=$R6,$I6,IF(AND(ISNUMBER($G6),ISNUMBER($F6)),IF($F6<=$R6,$G6,$E6),$E6)),IF(AND(ISNUMBER($G6),ISNUMBER($F6)),IF($F6<=$R6,$G6,$E6),$E6))*(1+IF($J6="Y",0,Assumptions!$B$3)),"") -> 1.0571 | V6: =IF(ISNUMBER($E6),IF(AND(ISNUMBER($I6),ISNUMBER($H6)),IF($H6<=$S6,$I6,IF(AND(ISNUMBER($G6),ISNUMBER($F6)),IF($F6<=$S6,$G6,$E6),$E6)),IF(AND(ISNUMBER($G6),ISNUMBER($F6)),IF($F6<=$S6,$G6,$E6),$E6))*(1+IF($J6="Y",0,Assumptions!$B$3)),"") -> 0.8459 | W6: =IF(ISNUMBER($T6),$Q6*$T6/Assumptions!$B$4,"") -> 2.926 | X6: =IF(ISNUMBER($U6),$R6*$U6/Assumptions!$B$5,"") -> 2.1142 | Y6: =IF(ISNUMBER($V6),$S6*$V6/Assumptions!$B$6,"") -> 1.6918 | Z6: =$A6&"|"&IF(ISNUMBER($W6),TEXT($W6,"0.0000"),"x")&"|"&$L6 -> H04|2.9260|Y | AA6: =$A6&"|"&IF(ISNUMBER($Y6),TEXT($Y6,"0.0000"),"x")&"|"&$L6 -> H04|1.6918|Y
A7: H04 | B7: Wiltronics (AU) | C7: 74HCT04 | D7: 1 | E7: 0.66 | F7: 10 | G7: 0.6 | H7: 25 | I7: 0.48 | J7: Y | K7: not shown | L7: Y | M7: 2026-10-25 | N7: https://www.wiltronics.com.au/product/320/74hct04-hex-inverter-3/ | O7: Wiltronics states prices include GST; no stock indicator on page. Not on preferred list but Australian retailer. DIP-14. element14 AU: no exact match for CD74HCT04E/SN74HCT04N. | P7: =IFERROR(VLOOKUP($A7,BOM!$A$2:$E$54,5,0),0) -> 2 | Q7: =CEILING($P7*Assumptions!$B$4/$D7,1) -> 2 | R7: =CEILING($P7*Assumptions!$B$5/$D7,1) -> 20 | S7: =CEILING($P7*Assumptions!$B$6/$D7,1) -> 200 | T7: =IF(ISNUMBER($E7),IF(AND(ISNUMBER($I7),ISNUMBER($H7)),IF($H7<=$Q7,$I7,IF(AND(ISNUMBER($G7),ISNUMBER($F7)),IF($F7<=$Q7,$G7,$E7),$E7)),IF(AND(ISNUMBER($G7),ISNUMBER($F7)),IF($F7<=$Q7,$G7,$E7),$E7))*(1+IF($J7="Y",0,Assumptions!$B$3)),"") -> 0.66 | U7: =IF(ISNUMBER($E7),IF(AND(ISNUMBER($I7),ISNUMBER($H7)),IF($H7<=$R7,$I7,IF(AND(ISNUMBER($G7),ISNUMBER($F7)),IF($F7<=$R7,$G7,$E7),$E7)),IF(AND(ISNUMBER($G7),ISNUMBER($F7)),IF($F7<=$R7,$G7,$E7),$E7))*(1+IF($J7="Y",0,Assumptions!$B$3)),"") -> 0.6 | V7: =IF(ISNUMBER($E7),IF(AND(ISNUMBER($I7),ISNUMBER($H7)),IF($H7<=$S7,$I7,IF(AND(ISNUMBER($G7),ISNUMBER($F7)),IF($F7<=$S7,$G7,$E7),$E7)),IF(AND(ISNUMBER($G7),ISNUMBER($F7)),IF($F7<=$S7,$G7,$E7),$E7))*(1+IF($J7="Y",0,Assumptions!$B$3)),"") -> 0.48 | W7: =IF(ISNUMBER($T7),$Q7*$T7/Assumptions!$B$4,"") -> 1.32 | X7: =IF(ISNUMBER($U7),$R7*$U7/Assumptions!$B$5,"") -> 1.2 | Y7: =IF(ISNUMBER($V7),$S7*$V7/Assumptions!$B$6,"") -> 0.96 | Z7: =$A7&"|"&IF(ISNUMBER($W7),TEXT($W7,"0.0000"),"x")&"|"&$L7 -> H04|1.3200|Y | AA7: =$A7&"|"&IF(ISNUMBER($Y7),TEXT($Y7,"0.0000"),"x")&"|"&$L7 -> H04|0.9600|Y
A8: H08 | B8: Core Electronics | C8: SN74HCT08N (SKU 002-595-SN74HCT08N) | D8: 1 | E8: 1.9 | F8: 10 | H8: 25 | J8: Y | K8: 0 local (out of stock) | L8: Y | M8: 2026-10-25 | N8: https://core-electronics.com.au/74hct08-quad-2-input-and-gate.html | O8: Third source. $1.90 inc GST; breaks shown ex GST only: 10+ $1.65, 25+ $1.61. Appears to be Mouser-sourced (002-595 prefix). | P8: =IFERROR(VLOOKUP($A8,BOM!$A$2:$E$54,5,0),0) -> 2 | Q8: =CEILING($P8*Assumptions!$B$4/$D8,1) -> 2 | R8: =CEILING($P8*Assumptions!$B$5/$D8,1) -> 20 | S8: =CEILING($P8*Assumptions!$B$6/$D8,1) -> 200 | T8: =IF(ISNUMBER($E8),IF(AND(ISNUMBER($I8),ISNUMBER($H8)),IF($H8<=$Q8,$I8,IF(AND(ISNUMBER($G8),ISNUMBER($F8)),IF($F8<=$Q8,$G8,$E8),$E8)),IF(AND(ISNUMBER($G8),ISNUMBER($F8)),IF($F8<=$Q8,$G8,$E8),$E8))*(1+IF($J8="Y",0,Assumptions!$B$3)),"") -> 1.9 | U8: =IF(ISNUMBER($E8),IF(AND(ISNUMBER($I8),ISNUMBER($H8)),IF($H8<=$R8,$I8,IF(AND(ISNUMBER($G8),ISNUMBER($F8)),IF($F8<=$R8,$G8,$E8),$E8)),IF(AND(ISNUMBER($G8),ISNUMBER($F8)),IF($F8<=$R8,$G8,$E8),$E8))*(1+IF($J8="Y",0,Assumptions!$B$3)),"") -> 1.9 | V8: =IF(ISNUMBER($E8),IF(AND(ISNUMBER($I8),ISNUMBER($H8)),IF($H8<=$S8,$I8,IF(AND(ISNUMBER($G8),ISNUMBER($F8)),IF($F8<=$S8,$G8,$E8),$E8)),IF(AND(ISNUMBER($G8),ISNUMBER($F8)),IF($F8<=$S8,$G8,$E8),$E8))*(1+IF($J8="Y",0,Assumptions!$B$3)),"") -> 1.9 | W8: =IF(ISNUMBER($T8),$Q8*$T8/Assumptions!$B$4,"") -> 3.8 | X8: =IF(ISNUMBER($U8),$R8*$U8/Assumptions!$B$5,"") -> 3.8 | Y8: =IF(ISNUMBER($V8),$S8*$V8/Assumptions!$B$6,"") -> 3.8 | Z8: =$A8&"|"&IF(ISNUMBER($W8),TEXT($W8,"0.0000"),"x")&"|"&$L8 -> H08|3.8000|Y | AA8: =$A8&"|"&IF(ISNUMBER($Y8),TEXT($Y8,"0.0000"),"x")&"|"&$L8 -> H08|3.8000|Y
A9: H08 | B9: Mouser Australia | C9: CD74HCT08E (595-CD74HCT08E) | D9: 1 | E9: 1.41 | F9: 10 | G9: 1.02 | H9: 100 | I9: 0.808 | J9: N | K9: 544 | L9: Y | M9: 2026-10-25 | N9: https://au.mouser.com/c/?q=CD74HCT08E | O9: Mouser page states no GST treatment; treated as ex GST. TI PDIP-14. | P9: =IFERROR(VLOOKUP($A9,BOM!$A$2:$E$54,5,0),0) -> 2 | Q9: =CEILING($P9*Assumptions!$B$4/$D9,1) -> 2 | R9: =CEILING($P9*Assumptions!$B$5/$D9,1) -> 20 | S9: =CEILING($P9*Assumptions!$B$6/$D9,1) -> 200 | T9: =IF(ISNUMBER($E9),IF(AND(ISNUMBER($I9),ISNUMBER($H9)),IF($H9<=$Q9,$I9,IF(AND(ISNUMBER($G9),ISNUMBER($F9)),IF($F9<=$Q9,$G9,$E9),$E9)),IF(AND(ISNUMBER($G9),ISNUMBER($F9)),IF($F9<=$Q9,$G9,$E9),$E9))*(1+IF($J9="Y",0,Assumptions!$B$3)),"") -> 1.551 | U9: =IF(ISNUMBER($E9),IF(AND(ISNUMBER($I9),ISNUMBER($H9)),IF($H9<=$R9,$I9,IF(AND(ISNUMBER($G9),ISNUMBER($F9)),IF($F9<=$R9,$G9,$E9),$E9)),IF(AND(ISNUMBER($G9),ISNUMBER($F9)),IF($F9<=$R9,$G9,$E9),$E9))*(1+IF($J9="Y",0,Assumptions!$B$3)),"") -> 1.122 | V9: =IF(ISNUMBER($E9),IF(AND(ISNUMBER($I9),ISNUMBER($H9)),IF($H9<=$S9,$I9,IF(AND(ISNUMBER($G9),ISNUMBER($F9)),IF($F9<=$S9,$G9,$E9),$E9)),IF(AND(ISNUMBER($G9),ISNUMBER($F9)),IF($F9<=$S9,$G9,$E9),$E9))*(1+IF($J9="Y",0,Assumptions!$B$3)),"") -> 0.8888 | W9: =IF(ISNUMBER($T9),$Q9*$T9/Assumptions!$B$4,"") -> 3.102 | X9: =IF(ISNUMBER($U9),$R9*$U9/Assumptions!$B$5,"") -> 2.244 | Y9: =IF(ISNUMBER($V9),$S9*$V9/Assumptions!$B$6,"") -> 1.7776 | Z9: =$A9&"|"&IF(ISNUMBER($W9),TEXT($W9,"0.0000"),"x")&"|"&$L9 -> H08|3.1020|Y | AA9: =$A9&"|"&IF(ISNUMBER($Y9),TEXT($Y9,"0.0000"),"x")&"|"&$L9 -> H08|1.7776|Y
A10: H08 | B10: element14 Australia | C10: SN74HCT08N (order code 3120497) | D10: 1 | E10: 1.37 | F10: 10 | G10: 0.89 | H10: 100 | I10: 0.739 | J10: N | K10: 577 (UK stock, 3-5 business days) | L10: Y | M10: 2026-10-25 | N10: https://au.element14.com/w/search?st=SN74HCT08N | O10: element14 shows ex GST with incl-GST in brackets; ex-GST figures recorded. TI DIP-14; incl GST 1.507/0.979/0.8129. | P10: =IFERROR(VLOOKUP($A10,BOM!$A$2:$E$54,5,0),0) -> 2 | Q10: =CEILING($P10*Assumptions!$B$4/$D10,1) -> 2 | R10: =CEILING($P10*Assumptions!$B$5/$D10,1) -> 20 | S10: =CEILING($P10*Assumptions!$B$6/$D10,1) -> 200 | T10: =IF(ISNUMBER($E10),IF(AND(ISNUMBER($I10),ISNUMBER($H10)),IF($H10<=$Q10,$I10,IF(AND(ISNUMBER($G10),ISNUMBER($F10)),IF($F10<=$Q10,$G10,$E10),$E10)),IF(AND(ISNUMBER($G10),ISNUMBER($F10)),IF($F10<=$Q10,$G10,$E10),$E10))*(1+IF($J10="Y",0,Assumptions!$B$3)),"") -> 1.507 | U10: =IF(ISNUMBER($E10),IF(AND(ISNUMBER($I10),ISNUMBER($H10)),IF($H10<=$R10,$I10,IF(AND(ISNUMBER($G10),ISNUMBER($F10)),IF($F10<=$R10,$G10,$E10),$E10)),IF(AND(ISNUMBER($G10),ISNUMBER($F10)),IF($F10<=$R10,$G10,$E10),$E10))*(1+IF($J10="Y",0,Assumptions!$B$3)),"") -> 0.979 | V10: =IF(ISNUMBER($E10),IF(AND(ISNUMBER($I10),ISNUMBER($H10)),IF($H10<=$S10,$I10,IF(AND(ISNUMBER($G10),ISNUMBER($F10)),IF($F10<=$S10,$G10,$E10),$E10)),IF(AND(ISNUMBER($G10),ISNUMBER($F10)),IF($F10<=$S10,$G10,$E10),$E10))*(1+IF($J10="Y",0,Assumptions!$B$3)),"") -> 0.8129 | W10: =IF(ISNUMBER($T10),$Q10*$T10/Assumptions!$B$4,"") -> 3.014 | X10: =IF(ISNUMBER($U10),$R10*$U10/Assumptions!$B$5,"") -> 1.958 | Y10: =IF(ISNUMBER($V10),$S10*$V10/Assumptions!$B$6,"") -> 1.6258 | Z10: =$A10&"|"&IF(ISNUMBER($W10),TEXT($W10,"0.0000"),"x")&"|"&$L10 -> H08|3.0140|Y | AA10: =$A10&"|"&IF(ISNUMBER($Y10),TEXT($Y10,"0.0000"),"x")&"|"&$L10 -> H08|1.6258|Y
A11: H32 | B11: Mouser Australia | C11: CD74HCT32E (595-CD74HCT32E) | D11: 1 | E11: 1.36 | F11: 10 | G11: 0.999 | H11: 100 | I11: 0.799 | J11: N | K11: 845 (+2000 due 19/11/2026) | L11: Y | M11: 2026-10-25 | N11: https://au.mouser.com/c/?q=CD74HCT32E | O11: Mouser page states no GST treatment; treated as ex GST. TI PDIP-14. | P11: =IFERROR(VLOOKUP($A11,BOM!$A$2:$E$54,5,0),0) -> 1 | Q11: =CEILING($P11*Assumptions!$B$4/$D11,1) -> 1 | R11: =CEILING($P11*Assumptions!$B$5/$D11,1) -> 10 | S11: =CEILING($P11*Assumptions!$B$6/$D11,1) -> 100 | T11: =IF(ISNUMBER($E11),IF(AND(ISNUMBER($I11),ISNUMBER($H11)),IF($H11<=$Q11,$I11,IF(AND(ISNUMBER($G11),ISNUMBER($F11)),IF($F11<=$Q11,$G11,$E11),$E11)),IF(AND(ISNUMBER($G11),ISNUMBER($F11)),IF($F11<=$Q11,$G11,$E11),$E11))*(1+IF($J11="Y",0,Assumptions!$B$3)),"") -> 1.496 | U11: =IF(ISNUMBER($E11),IF(AND(ISNUMBER($I11),ISNUMBER($H11)),IF($H11<=$R11,$I11,IF(AND(ISNUMBER($G11),ISNUMBER($F11)),IF($F11<=$R11,$G11,$E11),$E11)),IF(AND(ISNUMBER($G11),ISNUMBER($F11)),IF($F11<=$R11,$G11,$E11),$E11))*(1+IF($J11="Y",0,Assumptions!$B$3)),"") -> 1.0989 | V11: =IF(ISNUMBER($E11),IF(AND(ISNUMBER($I11),ISNUMBER($H11)),IF($H11<=$S11,$I11,IF(AND(ISNUMBER($G11),ISNUMBER($F11)),IF($F11<=$S11,$G11,$E11),$E11)),IF(AND(ISNUMBER($G11),ISNUMBER($F11)),IF($F11<=$S11,$G11,$E11),$E11))*(1+IF($J11="Y",0,Assumptions!$B$3)),"") -> 0.8789 | W11: =IF(ISNUMBER($T11),$Q11*$T11/Assumptions!$B$4,"") -> 1.496 | X11: =IF(ISNUMBER($U11),$R11*$U11/Assumptions!$B$5,"") -> 1.0989 | Y11: =IF(ISNUMBER($V11),$S11*$V11/Assumptions!$B$6,"") -> 0.8789 | Z11: =$A11&"|"&IF(ISNUMBER($W11),TEXT($W11,"0.0000"),"x")&"|"&$L11 -> H32|1.4960|Y | AA11: =$A11&"|"&IF(ISNUMBER($Y11),TEXT($Y11,"0.0000"),"x")&"|"&$L11 -> H32|0.8789|Y
A12: H32 | B12: Wiltronics (AU) | C12: 74HCT32 | D12: 1 | E12: 0.66 | F12: 10 | G12: 0.6 | H12: 25 | I12: 0.48 | J12: Y | K12: not shown | L12: Y | M12: 2026-10-25 | N12: https://wiltronics.com.au/?p=335 | O12: Wiltronics states prices include GST; no stock indicator on page. Not on preferred list but Australian retailer. DIP-14. Core Electronics also lists SN74HCT32N at $2.55 inc GST, 0 local stock. | P12: =IFERROR(VLOOKUP($A12,BOM!$A$2:$E$54,5,0),0) -> 1 | Q12: =CEILING($P12*Assumptions!$B$4/$D12,1) -> 1 | R12: =CEILING($P12*Assumptions!$B$5/$D12,1) -> 10 | S12: =CEILING($P12*Assumptions!$B$6/$D12,1) -> 100 | T12: =IF(ISNUMBER($E12),IF(AND(ISNUMBER($I12),ISNUMBER($H12)),IF($H12<=$Q12,$I12,IF(AND(ISNUMBER($G12),ISNUMBER($F12)),IF($F12<=$Q12,$G12,$E12),$E12)),IF(AND(ISNUMBER($G12),ISNUMBER($F12)),IF($F12<=$Q12,$G12,$E12),$E12))*(1+IF($J12="Y",0,Assumptions!$B$3)),"") -> 0.66 | U12: =IF(ISNUMBER($E12),IF(AND(ISNUMBER($I12),ISNUMBER($H12)),IF($H12<=$R12,$I12,IF(AND(ISNUMBER($G12),ISNUMBER($F12)),IF($F12<=$R12,$G12,$E12),$E12)),IF(AND(ISNUMBER($G12),ISNUMBER($F12)),IF($F12<=$R12,$G12,$E12),$E12))*(1+IF($J12="Y",0,Assumptions!$B$3)),"") -> 0.6 | V12: =IF(ISNUMBER($E12),IF(AND(ISNUMBER($I12),ISNUMBER($H12)),IF($H12<=$S12,$I12,IF(AND(ISNUMBER($G12),ISNUMBER($F12)),IF($F12<=$S12,$G12,$E12),$E12)),IF(AND(ISNUMBER($G12),ISNUMBER($F12)),IF($F12<=$S12,$G12,$E12),$E12))*(1+IF($J12="Y",0,Assumptions!$B$3)),"") -> 0.48 | W12: =IF(ISNUMBER($T12),$Q12*$T12/Assumptions!$B$4,"") -> 0.66 | X12: =IF(ISNUMBER($U12),$R12*$U12/Assumptions!$B$5,"") -> 0.6 | Y12: =IF(ISNUMBER($V12),$S12*$V12/Assumptions!$B$6,"") -> 0.48 | Z12: =$A12&"|"&IF(ISNUMBER($W12),TEXT($W12,"0.0000"),"x")&"|"&$L12 -> H32|0.6600|Y | AA12: =$A12&"|"&IF(ISNUMBER($Y12),TEXT($Y12,"0.0000"),"x")&"|"&$L12 -> H32|0.4800|Y
A13: H32 | B13: element14 Australia | C13: SN74HCT32N (order code 3120505) | D13: 1 | E13: 1.4 | F13: 10 | G13: 0.897 | H13: 100 | I13: 0.739 | J13: N | K13: 0 on hand; available to order, deliveries from 02/01/2027, 16 wk lead | L13: Y | M13: 2026-10-25 | N13: https://au.element14.com/w/search?st=SN74HCT32N | O13: element14 shows ex GST with incl-GST in brackets; ex-GST figures recorded. TI DIP-14. | P13: =IFERROR(VLOOKUP($A13,BOM!$A$2:$E$54,5,0),0) -> 1 | Q13: =CEILING($P13*Assumptions!$B$4/$D13,1) -> 1 | R13: =CEILING($P13*Assumptions!$B$5/$D13,1) -> 10 | S13: =CEILING($P13*Assumptions!$B$6/$D13,1) -> 100 | T13: =IF(ISNUMBER($E13),IF(AND(ISNUMBER($I13),ISNUMBER($H13)),IF($H13<=$Q13,$I13,IF(AND(ISNUMBER($G13),ISNUMBER($F13)),IF($F13<=$Q13,$G13,$E13),$E13)),IF(AND(ISNUMBER($G13),ISNUMBER($F13)),IF($F13<=$Q13,$G13,$E13),$E13))*(1+IF($J13="Y",0,Assumptions!$B$3)),"") -> 1.54 | U13: =IF(ISNUMBER($E13),IF(AND(ISNUMBER($I13),ISNUMBER($H13)),IF($H13<=$R13,$I13,IF(AND(ISNUMBER($G13),ISNUMBER($F13)),IF($F13<=$R13,$G13,$E13),$E13)),IF(AND(ISNUMBER($G13),ISNUMBER($F13)),IF($F13<=$R13,$G13,$E13),$E13))*(1+IF($J13="Y",0,Assumptions!$B$3)),"") -> 0.9867 | V13: =IF(ISNUMBER($E13),IF(AND(ISNUMBER($I13),ISNUMBER($H13)),IF($H13<=$S13,$I13,IF(AND(ISNUMBER($G13),ISNUMBER($F13)),IF($F13<=$S13,$G13,$E13),$E13)),IF(AND(ISNUMBER($G13),ISNUMBER($F13)),IF($F13<=$S13,$G13,$E13),$E13))*(1+IF($J13="Y",0,Assumptions!$B$3)),"") -> 0.8129 | W13: =IF(ISNUMBER($T13),$Q13*$T13/Assumptions!$B$4,"") -> 1.54 | X13: =IF(ISNUMBER($U13),$R13*$U13/Assumptions!$B$5,"") -> 0.9867 | Y13: =IF(ISNUMBER($V13),$S13*$V13/Assumptions!$B$6,"") -> 0.8129 | Z13: =$A13&"|"&IF(ISNUMBER($W13),TEXT($W13,"0.0000"),"x")&"|"&$L13 -> H32|1.5400|Y | AA13: =$A13&"|"&IF(ISNUMBER($Y13),TEXT($Y13,"0.0000"),"x")&"|"&$L13 -> H32|0.8129|Y
A14: H86 | B14: Mouser Australia | C14: CD74HCT86E (595-CD74HCT86E) | D14: 1 | E14: 1.64 | F14: 10 | G14: 1.17 | H14: 100 | I14: 0.924 | J14: N | K14: 2754 | L14: Y | M14: 2026-10-25 | N14: https://au.mouser.com/c/?q=CD74HCT86E | O14: Mouser page states no GST treatment; treated as ex GST. TI PDIP-14. Alt on same page: CD74HCT86EE4 571 stock, 1.62/1.20/0.924. | P14: =IFERROR(VLOOKUP($A14,BOM!$A$2:$E$54,5,0),0) -> 2 | Q14: =CEILING($P14*Assumptions!$B$4/$D14,1) -> 2 | R14: =CEILING($P14*Assumptions!$B$5/$D14,1) -> 20 | S14: =CEILING($P14*Assumptions!$B$6/$D14,1) -> 200 | T14: =IF(ISNUMBER($E14),IF(AND(ISNUMBER($I14),ISNUMBER($H14)),IF($H14<=$Q14,$I14,IF(AND(ISNUMBER($G14),ISNUMBER($F14)),IF($F14<=$Q14,$G14,$E14),$E14)),IF(AND(ISNUMBER($G14),ISNUMBER($F14)),IF($F14<=$Q14,$G14,$E14),$E14))*(1+IF($J14="Y",0,Assumptions!$B$3)),"") -> 1.804 | U14: =IF(ISNUMBER($E14),IF(AND(ISNUMBER($I14),ISNUMBER($H14)),IF($H14<=$R14,$I14,IF(AND(ISNUMBER($G14),ISNUMBER($F14)),IF($F14<=$R14,$G14,$E14),$E14)),IF(AND(ISNUMBER($G14),ISNUMBER($F14)),IF($F14<=$R14,$G14,$E14),$E14))*(1+IF($J14="Y",0,Assumptions!$B$3)),"") -> 1.287 | V14: =IF(ISNUMBER($E14),IF(AND(ISNUMBER($I14),ISNUMBER($H14)),IF($H14<=$S14,$I14,IF(AND(ISNUMBER($G14),ISNUMBER($F14)),IF($F14<=$S14,$G14,$E14),$E14)),IF(AND(ISNUMBER($G14),ISNUMBER($F14)),IF($F14<=$S14,$G14,$E14),$E14))*(1+IF($J14="Y",0,Assumptions!$B$3)),"") -> 1.0164 | W14: =IF(ISNUMBER($T14),$Q14*$T14/Assumptions!$B$4,"") -> 3.608 | X14: =IF(ISNUMBER($U14),$R14*$U14/Assumptions!$B$5,"") -> 2.574 | Y14: =IF(ISNUMBER($V14),$S14*$V14/Assumptions!$B$6,"") -> 2.0328 | Z14: =$A14&"|"&IF(ISNUMBER($W14),TEXT($W14,"0.0000"),"x")&"|"&$L14 -> H86|3.6080|Y | AA14: =$A14&"|"&IF(ISNUMBER($Y14),TEXT($Y14,"0.0000"),"x")&"|"&$L14 -> H86|2.0328|Y
